Workbook
Name \A: #REF!
Name \B: #REF!
Name \E: #REF!
Name \H: #REF!
Name \L: #REF!
Name \M: #REF!
Name \O: #REF!
Name \S: #REF!
Name \V: #REF!
Name \W: #REF!
Name a: #REF!
Name ABC: #REF!
Name adjfasl: #REF!
Name adjfasl: #REF!
Name adjfasl: #REF!
Name adjfasl: #REF!
Name adjfasl: #REF!
Name adjfasl: #REF!
Name adjfasl: #REF!
Name admin_3_2: #REF!
Name admin_cross: #REF!
Name AU_329: #REF!
Name b: #REF!
Name C_: #REF!
Name CF: #REF!
Name cogos: #REF!
Name cogos_cross: #REF!
Name cogos_detail: #REF!
Name cogs: #REF!
Name consumer: #REF!
Name COST: #REF!
Name d: #REF!
Name DETAILS: #REF!
Name discount: #REF!
Name DME: #REF!
Name DRAWB: #REF!
Name DRSUP: #REF!
Name ER: #REF!
Name EXCH: #REF!
Name f: #REF!
Name financialcharges: #REF!
Name g: #REF!
Name gratuity: #REF!
Name hffix: #REF!
Name L: #REF!
Name LACHM: #REF!
Name LACHMN: #REF!
Name List_LevelAssurance: #REF!
Name List_TypeProcedure: #REF!
Name LMR: #REF!
Name m: #REF!
Name MENU: #REF!
Name n: #REF!
Name nid: #REF!
Name nnumb: #REF!
Name nnumb1: #REF!
Name nokia206: #REF!
Name nokia206: #REF!
Name NUMB: #REF!
Name numbers: #REF!

Sheet Con BS
A1: PAKISTAN INSTITUTE OF LABOUR EDUCATION AND RESEARCH
A2: STATEMENT OF FINANCIAL POSITION
A3: AS AT JUNE 30, 2026
I6: 2026 | L6: 2025 | N6: 2024
G7: Note | I7: Rupees | K7: Note | L7: Rupees | N7: Rupees
A8: ASSETS
A9: Non - Current Assets
A10: Property and equipment | G10: ='PPE-Note-4'!A1 -> 5 | I10: ='PPE-Note-4'!O116 -> 14035031 | K10: =+'PPE-Note-4'!A1 -> 5 | L10: ='PPE-Note-4'!O59 -> 15295085 | N10: ='PPE-Note-4'!O42 -> 16140069 | Q10: =N10-L10 -> 844984 | Z10: 20916309 | AA10: =+Z10-N10 -> 4776240
A11: Intangible assets | G11: ='Con 5-18'!A2 -> 6 | K11: =+'Con 5-18'!A2 -> 6 | L11: ='Con 5-18'!M9 -> 5815 | N11: ='Con 5-18'!O15 -> 8722 | Q11: =N11-L11 -> 2907
A12: Security deposits | L12: 0 | N12: 0 | Q12: =N12-L12 -> 0
I13: =SUM(I10:I12) -> 14035031 | L13: =SUM(L10:L12) -> 15300900 | N13: =SUM(N10:N12) -> 16148791
A15: Current Assets
A16: Advances, deposits and other receivables | G16: ='Con 5-18'!A36 -> 7 | K16: =+'Con 5-18'!A36 -> 7 | L16: =ROUND('Con 5-18'!M47, 0) -> #REF! | N16: ='Con 5-18'!O47 -> 1710587 | Q16: =N16-L16 -> #REF!
A17: Bank balances | G17: ='Con 5-18'!A49 -> 8 | K17: =+'Con 5-18'!A49 -> 8 | L17: =ROUND('Con 5-18'!M54, 0) -> #REF! | N17: ='Con 5-18'!O54 -> 2725572.5 | Q17: =N17-L17 -> #REF!
I18: =SUM(I16:I17) -> 0 | L18: =SUM(L16:L17) -> #REF! | N18: =SUM(N16:N17) -> 4436159.5 | Y18: =#REF!-N18 -> #REF!
A20: TOTAL ASSETS | I20: =SUM(I13,I18) -> 14035031 | L20: =SUM(L13,L18) -> #REF! | N20: =SUM(N13,N18) -> 20584951
A22: FUNDS AND LIABILITIES
A23: Fund balance | L23: =ROUND(SOCE!M32,0) -> -27233980 | N23: =+SOCE!M28 -> -30425260 | Q23: =L23-N23 -> 3191280.5
A25: Non - Current Liabilities
A26: Lease liabilities | L26: 0 | N26: 0 | Q26: =L26-N26 -> 0 | Z26: =+N26-#REF! -> #REF!
A28: Current Liabilities
A29: Current portion of lease liabilities | L29: 0 | N29: 0 | Q29: =L29-N29 -> 0 | Z29: =+N29-#REF! -> #REF!
A30: Accrued and other liabilities | G30: ='Con 5-18'!A70 -> 9 | K30: =+'Con 5-18'!A70 -> 9 | L30: =ROUND('Con 5-18'!M76,0) -> 9804523 | N30: ='Con 5-18'!O76 -> 10219196 | Q30: =L30-N30 -> -414673 | Z30: =+N30-#REF! -> #REF!
A31: Taxation - net | L31: =-ROUND(GETPIVOTDATA("Sum of Amount",'Pivot 2025'!$A$3,"FSL1","Profit and Loss","FSL2","Taxation","FSL3","Income Tax Expenses","FSL 4","Income Tax Expenses"),0)+'Adjustments 2025'!F78 -> 186605 | N31: 0
A32: Short term liabilities | G32: ='Con 5-18'!A78 -> 10 | K32: =+'Con 5-18'!A78 -> 10 | L32: =ROUND('Con 5-18'!M82,0) -> #REF! | N32: ='Con 5-18'!O82 -> 40791015 | Q32: =L32-N32 -> #REF! | S32: =L32-39791015 -> #REF! | Z32: =+N32-#REF! -> #REF!
I33: =SUM(I29:I32) -> 0 | L33: =SUM(L29:L32) -> #REF! | N33: =N30+N32+N29 -> 51010211
A35: TOTAL FUNDS AND LIABILITIES | I35: =+I23+I26+I33 -> 0 | L35: =+L23+L26+L33 -> #REF! | N35: =+N23+N26+N33 -> 20584951
L37: =L35-L20 -> #REF! | Q37: =+L35-L20 -> #REF! | R37: =N35-N20 -> 0
A38: ="The annexed notes form an integral part of these financial statements." -> The annexed notes form an integral part of these financial statements.
Q39: =+GETPIVOTDATA("Sum of Amount",'Pivot 2025'!$A$3,"FSL1","-","FSL2","Inter Project Balances") -> 0.47 | R39: Difference of inter project balance
Q40: =-GETPIVOTDATA("Sum of Amount",'Pivot 2025'!$A$3) -> -0.85163715 | R40: Difference of TB
Q41: =+SOCE!AL25 -> 5815.06 | R41: Difference of fund balance - opening
Q43: =SUM(Q39:Q42) -> 5814.6784
Q45: =+Q37-Q43 -> #REF!
B61: Chief Executive Officer | G61: Director
G350: 9788859 | K350: 9788859 | M350: 9788859
C351: Short term Liabilities | G351: 39791015 | K351: 39791015 | M351: 39791015
P401: 0

Sheet Con I EX
A1: PAKISTAN INSTITUTE OF LABOUR EDUCATION AND RESEARCH
A2: STATEMENT OF INCOME AND EXPENDITURE
A3: FOR THE YEAR ENDED JUNE 30, 2025
I6: 2026 | K6: 2025 | M6: 2024
G7: Note | I7: Rupees | K7: Rupees | M7: Rupees | N7: Chief Executive Officer | S7: Director
A9: Income from donations | K9: =+-ROUND(GETPIVOTDATA("Sum of Amount",'Pivot 2025'!$A$3,"FSL1","Profit and Loss","FSL2","Income From Donations","FSL3","Income From Donations"),0) -> 36461449 | M9: 19036148 | N9: 46013529 | P9: #REF! | S9: 70923139
A11: Operating cost | G11: =+'Con 5-18'!A107 -> 11 | K11: =-GETPIVOTDATA("Sum of Amount",'Pivot 2025'!$A$3,"FSL1","Profit and Loss","FSL2","Operating Costs") -> -25789481 | M11: =-'Con 5-18'!O138 -> -15852917 | N11: =+-'Con 5-18'!P138 -> #REF! | P11: =+-'Con 5-18'!R138 -> #REF! | S11: =+-'Con 5-18'!T138 -> #REF!
A12: Administrative and general expenses | G12: =+'Con 5-18'!A140 -> 12 | K12: =-ROUND('Con 5-18'!M168,0) -> -7605812 | M12: =-'Con 5-18'!O168 -> -4463948 | N12: =+-'Con 5-18'!P168 -> #REF! | P12: =+-'Con 5-18'!R168 -> #REF! | S12: =+-'Con 5-18'!T168 -> -29875202
K13: =SUM(K11:K12) -> -33395293 | M13: =SUM(M11:M12) -> -20316865 | N13: =SUM(N11:N12) -> #REF! | P13: =SUM(P11:P12) -> #REF! | S13: =S11+S12 -> #REF!
A15: Surplus / (deficit) from operating activities | K15: =K9+K13 -> 3066156 | M15: =M9+M13 -> -1280717 | N15: =N9+N13 -> #REF! | P15: =P9+P13 -> #REF! | S15: =S9+S13 -> #REF!
A17: Other income | G17: =+'Con 5-18'!A188 -> 13 | K17: =ROUND('Con 5-18'!M196,0) -> 821846 | M17: ='Con 5-18'!O196 -> 1640088.5 | N17: =+'Con 5-18'!P196 -> 786976.53 | P17: =+'Con 5-18'!R196 -> #REF! | S17: =+'Con 5-18'!T196 -> 1363912.1
A18: Financial charges | G18: =+'Con 5-18'!A204 -> 14 | K18: =-ROUND('Con 5-18'!M209,0) -> -17863 | M18: =-'Con 5-18'!O209 -> -365187 | N18: =-'Con 5-18'!P209 -> #REF! | P18: #REF! | S18: 0
A20: Surplus / (deficit) before income tax | K20: =K15+K17+K18 -> 3870139 | M20: =M15+M17+M18 -> -5815.4515 | N20: =N15+N17+N18 -> #REF! | P20: =P15+P17+P18 -> #REF! | S20: =S15+S17+S18 -> #REF!
A22: Minimum tax differential | K22: 0 | M22: 0
A24: Deficit before income tax | K24: =SUM(K20:K23) -> 3870139 | M24: =SUM(M20:M23) -> -5815.4515
A26: Taxation
A27: - | B27: Current tax | K27: =-'Adjustments 2025'!E77 -> -678859 | M27: 0
A29: Surplus / (deficit) for the year | K29: =+K20+K27 -> 3191280 | M29: =+M20+M27 -> -5815.4515 | N29: =+N20+#REF! -> #REF! | P29: =+P20+#REF! -> #REF! | S29: =+S20+#REF! -> #REF! | Z29: =+N29+3049662 -> #REF!
A32: ='Con BS'!A38 -> The annexed notes form an integral part of these financial statements.
V38: f
B60: Chief Executive Officer | G60: Director
F350: 9788859 | G350: 9788859 | L350: 9788859
C351: Short term Liabilities | F351: 39791015 | G351: 39791015 | L351: 39791015
O401: 0

Sheet SOCE
A1: PAKISTAN INSTITUTE OF LABOUR EDUCATION AND RESEARCH
A2: STATEMENT OF CHANGES IN NET ASSETS
A3: ='Con I EX'!A3 -> FOR THE YEAR ENDED JUNE 30, 2025
H6: Accumulated deficit | J6: Total fund balance | M6: Accumulated deficit | O6: Total fund balance
AL8: `
H10: ---------------- Rupees -------------- | M10: ---------------- Rupees -------------- | AL10: `
A12: Balance as at June 30, 2014 | I12: 50097736 | N12: 50097736 | P12: =N12 -> 50097736
A14: Restatement - Note 3.10 | I14: 0 | N14: 0 | P14: =N14 -> 0
R15: 43840937
A16: Balance as at July 01, 2018 | H16: 8021729.1 | J16: =H16 -> 8021729.1 | M16: 8021729.1 | O16: =M16 -> 8021729.1
A18: (Deficit) for the year ended June 30, 2018 | H18: -12489404 | J18: =H18 -> -12489404 | M18: -12489404 | O18: =M18 -> -12489404
A20: Balance as at July 01, 2022 | H20: -22020234 | J20: =+H20 -> -22020234 | M20: -22020234 | O20: =+M20 -> -22020234
A22: Surplus for the year ended June 30, 2023 | H22: 22288181 | J22: =H22 -> 22288181 | M22: 22288181 | O22: =M22 -> 22288181
A24: Balance as at July 01, 2023 | H24: -30419445 | J24: =+H24 -> -30419445 | M24: -30419445 | O24: =+M24 -> -30419445 | AL24: =+GETPIVOTDATA("Sum of Amount",'Pivot 2025'!$A$3,"FSL1","Balance Sheet","FSL2","Fund Balance") -> 30425260
AL25: =+AL24+M24 -> 5815.06
A26: Deficit for the year ended June 30, 2024 | H26: =+'Con I EX'!H29 -> 0 | J26: =+H26 -> 0 | M26: =+'Con I EX'!M29 -> -5815.4515 | O26: =+M26 -> -5815.4515
A28: Balance as at June 30, 2024 | H28: =+H24+H26 -> -30419445 | J28: =+J24+J26 -> -30419445 | M28: =+M24+M26 -> -30425260 | O28: =+O24+O26 -> -30425260
A30: Surplus for the year ended June 30, 2025 | H30: ='Con I EX'!F29 -> 0 | J30: =+H30 -> 0 | M30: ='Con I EX'!K29 -> 3191280 | O30: =+M30 -> 3191280
A32: Balance as at June 30, 2025 | H32: =+H28+H30 -> -30419445 | J32: =+J28+J30 -> -30419445 | M32: =+M28+M30 -> -27233980 | O32: =+O28+O30 -> -27233980
A35: ='Con BS'!A38 -> The annexed notes form an integral part of these financial statements.
S36: =#REF!-#REF! -> #REF!
B68: Chief Executive Officer | G68: Director
F350: 9788859 | G350: 9788859 | N350: 9788859
C351: Short term Liabilities | F351: 39791015 | G351: 39791015 | N351: 39791015
Q401: 0

Sheet CFS
A1: PAKISTAN INSTITUTE OF LABOUR EDUCATION AND RESEARCH
A2: STATEMENT OF CASH FLOWS
A3: =+SOCE!A3 -> FOR THE YEAR ENDED JUNE 30, 2025
H6: 2025 | J6: 2024 | L6: 2016
G7: Note | H7: Rupees | J7: Rupees | L7: Rupees
A8: CASH FLOW FROM OPERATING ACTIVITIES
A9: =+'Con I EX'!A20 -> Surplus / (deficit) before income tax | H9: ='Con I EX'!K20 -> 3870139 | J9: -5815 | L9: =+'Con I EX'!P20 -> #REF! | O9: =ROUND(J9,0) -> -5815
A10: Adjustment for non cash items : | O10: =ROUND(J10,0) -> 0
A11: Depreciation | H11: =-'PPE-Note-4'!O51 -> 869984 | J11: 935314 | L11: =+#REF! -> #REF! | O11: =ROUND(J11,0) -> 935314
A12: Amortization of intangible assets | H12: =-'Con 5-18'!M7 -> 2907 | J12: 4361 | L12: 0
A13: (Gain) on disposal of property and equipment | H13: 0 | J13: 0 | L13: 0
A14: Provision for gratuity | H14: 0 | J14: 0 | L14: =-2898650-L23 -> 1959879 | O14: =ROUND(J14,0) -> 0
A15: Gain on disposal of property and equipment | H15: =+-'Con 5-18'!M193 -> 0 | J15: 0
A16: Financial charges | H16: ='Con 5-18'!M209 -> 17863 | J16: 365187 | L16: 248810 | O16: =ROUND(J16,0) -> 365187
A17: Operating surplus before working capital changes | H17: =SUM(H9:H16) -> 4760893 | J17: 1299047 | L17: =SUM(L8:L16) -> #REF! | O17: =SUM(O9:O16) -> 1294686 | Q17: -17602669
O18: =ROUND(J18,0) -> 0 | Q18: 196453
A19: Decrease in current assets | H19: =(+'Con BS'!N16-'Con BS'!L16)+('Con BS'!N12-'Con BS'!L12) -> #REF! | J19: 300198 | L19: 196453 | O19: =ROUND(J19,0) -> 300198 | Q19: 553358
A20: Increase in current liabilities | H20: =+'Con 5-18'!M72-'Con 5-18'!O72+'Con 5-18'!M73-'Con 5-18'!O73+('Con BS'!L26-'Con BS'!N26)+('Con BS'!L29-'Con BS'!N29) -> -414673 | J20: -683288 | L20: 553358 | O20: =ROUND(J20,0) -> -683288 | Q20: -248810
O21: =ROUND(J21,0) -> 0 | Q21: =+Q17+Q18+Q19+Q20 -> -17101668
A22: Taxes paid | H22: 0 | J22: 0
A23: Staff gratuity paid | H23: 0 | J23: 0 | L23: -4858529 | N23: -14596848
A24: Financial charges paid | H24: =-H16 -> -17863 | J24: -365187 | L24: =-L16 -> -248810 | O24: =ROUND(J24,0) -> -365187 | Q24: 11793034
A25: Taxes paid | H25: =+'Con I EX'!K27+'Con BS'!L31 -> -492254 | J25: 0
A27: Net cash inflow from operating activities | H27: =SUM(H17:H26) -> #REF! | J27: =SUM(J17:J26) -> 550770 | L27: =SUM(L17:L24) -> #REF! | O27: =SUM(O17:O24) -> 546409 | Q27: 6817000
O28: =ROUND(J28,0) -> 0 | Q28: =+Q21+Q24+Q27 -> 1508366
A29: CASH FLOW FROM INVESTING ACTIVITIES | O29: =ROUND(J29,0) -> 0
A30: Sale proceeds of property and equipment | H30: 0 | J30: 0
A31: Capital expenditure | H31: 0 | J31: 0 | L31: =+-#REF! -> #REF! | O31: =ROUND(J31,0) -> 0
A32: Additions in intangible assets | H32: =-'Con 5-18'!M6 -> 0 | J32: 0 | L32: 0
A33: Sale proceeds of property and equipment | H33: 0 | J33: 0 | L33: 0
A34: Net cash inflow from investing activities | H34: =SUM(H30) -> 0 | J34: 0
O35: =ROUND(J35,0) -> 0
A36: CASH FLOW FROM FINANCING ACTIVITIES | O36: =ROUND(J36,0) -> 0
A37: Capital expenditure inccured | H37: =-'PPE-Note-4'!O46 -> -25000 | J37: 0
A38: Short term liabilities - net | H38: =+'Con BS'!L32-'Con BS'!N32 -> #REF! | J38: 1000000 | L38: 11796035 | O38: =ROUND(J38,0) -> 1000000
A39: Lease liabilities - net | H39: 0 | J39: 0 | L39: 6850000 | O39: =ROUND(J39,0) -> 0
A40: Net cash (used in) / inflow from financing activities | H40: =+H38+H39+H37 -> #REF! | J40: 1000000 | L40: =SUM(L38) -> 11796035 | O40: =ROUND(J40,0) -> 1000000
O41: =ROUND(J41,0) -> 0
A42: Net increase in cash and cash equivalent | H42: =SUM(H27,H34,H40) -> #REF! | J42: 1550770 | L42: =SUM(L27,L34,L40) -> #REF! | O42: =SUM(O27,O34,O40) -> 1546409
O43: =ROUND(J43,0) -> 0
...

Sheet Con 1-3 (New)
A1: PAKISTAN INSTITUTE OF LABOUR EDUCATION AND RESEARCH
A2: NOTES TO THE FINANCIAL STATEMENTS
A3: =CFS!A3 -> FOR THE YEAR ENDED JUNE 30, 2025
A6: 1. | B6: THE INSTITUTE AND ITS ACTIVITIES
B8: =+A6+0.1 -> 1.1 | C8: Pakistan Institute of Labour Education and Research (hereinafter referred to as the Institute or PILER), is a non-government and not for profit organization. It was established in the year 1982 and was registered under the Voluntary Social Welfare Agencies Ordinance 1961. The Institute has now incorporated as company limited by guarantee on 5th September 2012 under section 42 of the Companies Ordinance, 1984 (repealed by Companies Act, 2017). The Institute has been engaged in education, research, training and advocacy in the areas of labour rights and labour legislation, social justice and human development, regional solidarity and peace. The registered office of Pakistan Institute of Labour Education and Research is 24GF+3HG, Sector X-6 Sector X Gulshan-e-Maymar, Karachi.
M16: 2025 | O16: 2024 | Q16: =+"During the year, the company incurred a deficit after tax of Rs. "&M20&" million (2024: Rs. "&O20&" million) which resulted in negative fund balance of Rs. "&M21&" million (2024: Rs. "&O21&" million) as of the date of financial position." -> During the year, the company incurred a deficit after tax of Rs. -3.19 million (2024: Rs. 0.01 million) which resulted in negative fund balance of Rs. 27.23 million (2024: Rs. 30.43 million) as of the date of financial position.
B17: =+B8+0.1 -> 1.2 | C17: =CONCATENATE(Q16," ",Q17," ",Q18) -> During the year, the company incurred a deficit after tax of Rs. -3.19 million (2024: Rs. 0.01 million) which resulted in negative fund balance of Rs. 27.23 million (2024: Rs. 30.43 million) as of the date of financial position. However, the management believes that the adverse financial position will not affect the primary objectives of the company. Further, the major lender, who is also a related party due to common directorship, has also confirmed its financial commitment for future needs of the company. Accordingly, the company will be able to continue its operations in the foreseeable future. | Q17: However, the management believes that the adverse financial position will not affect the primary objectives of the company. Further, the major lender, who is also a related party due to common directorship, has also confirmed its financial commitment for future needs of the company.
M18: =+'Con I EX'!K29 -> 3191280 | O18: =+'Con I EX'!M29 -> -5815.4515 | Q18: Accordingly, the company will be able to continue its operations in the foreseeable future.
M19: =+'Con BS'!L23 -> -27233980 | O19: =+'Con BS'!N23 -> -30425260
M20: =ROUND(-M18/1000000, 2) -> -3.19 | O20: =ROUND(-O18/1000000, 2) -> 0.01
M21: =ROUND(-M19/1000000, 2) -> 27.23 | O21: =ROUND(-O19/1000000, 2) -> 30.43
A24: =+A6+1 -> 2 | B24: BASIS OF PREPARATION
B26: =+A24+0.1 -> 2.1 | C26: Statement of compliance
C28: These financial statements have been prepared in accordance with approved accounting standards, as applicable in Pakistan. Approved accounting standards comprise of Revised Accounting and Financial Reporting Standard for Small-sized Entities (AFRS for SSEs) and Accounting Standard for Not for Profit Organisations (NPOs) issued by Institute of Chartered Accountants of Pakistan (ICAP).
C33: These financial statements have been prepared in accordance with the accounting and reporting standards as applicable in Pakistan. The accounting and reporting standards as applicable in Pakistan comprise of:
C36: - | D36: Revised Accounting and Financial Reporting Standard for Small-sized Entities (AFRS for SSEs) issued by ICAP in 2015 and Accounting Standard for Not for Profit Organization (Accounting standards for NPOs) issued by the Institute of Chartered Accountants of Pakistan as notified under Companies Act, 2017; and
C40: - | D40: Provisions of and directives issued under the Companies Act, 2017.
C42: Where the provisions of and directives issued under the Companies Act, 2017 differ, the provisions of and directives issued under the Companies Act, 2017 have been followed.
B51: =+B26+0.1 -> 2.2 | C51: Critical accounting estimates and judgements
C53: The preparation of these financial statements is in conformity with approved accounting standards requires the use of certain critical accounting estimates. It also requires management to exercise its judgement in the process of applying the company's accounting policies.
C57: Estimates and judgements are continually evaluated and are based on historical experience and other factors, including expectations of future events that are believed to be reasonable under the circumstances.
C60: The estimates and underlying assumptions are reviewed on an ongoing basis. Revisions to accounting estimates are recognized in the period in which the estimate is revised if the revision affects only that period of the revision and future periods if the revision affects both current and future periods.
C64: Judgements are made by management in the application of approved accounting standards, that have significant effect on the financial statements and estimates with a significant risk of material adjustment in the next year.
A67: =+A24+1 -> 3 | B67: CHANGE IN ACCOUNTING POLICY
B69: During the year, the company transitioned its accounting policy from International Financial Reporting Standards (IFRS) to the Accounting and Financial Reporting framework for Small-Sized Entities (AFRS for SSE).
A78: =+A67+1 -> 4 | B78: MATERIAL ACCOUNTING POLICIES INFORMATION
B80: =+A78+0.1 -> 4.1 | C80: Property and equipment
C82: Property and equipment are stated at cost less accumulated depreciation.
C84: Whenever project agreement requires, capital items are expensed out in the period in which it was acquired.
C86: Depreciation is computed applying the straight line method at the rates given in note 5 to the financial statements. The residual values of the assets are considered zero while calculating depreciation.
C89: Depreciation on additions is charged from the month in which the asset is put to use and on disposals up to the month of disposal.
C92: Maintenance and normal repairs are charged to statement of income and expenditure as and when incurred. Major renewals and improvements are capitalized. Gain or loss on disposal of assets, if any, is included in statement of income and expenditure.
B96: =B80+0.1 -> 4.2 | C96: Intangibles
C98: An intangible asset is recognised if it is probable that the future economic benefits that are attributable to the asset will flow to the Company and that the cost of such asset can also be measured reliably.
C101: Generally, costs associated with developing or maintaining computer software programmes are recognised as an expense as incurred. However, costs that are directly associated with identifiable software and have probable economic benefits exceeding one year, are recognised as an intangible asset. Direct costs include the purchase cost of software and related overhead cost. Intangible assets acquired separately are measured on initial recognition at cost. Following initial recognition, intangible assets are carried at cost less accumulated amortisation and accumulated impairment losses, if any.
C108: Amortisation is charged to the statement of income and expenditure applying the reducing balance method, whereby, the cost of intangible asset is written off over its useful economic life. The amortization rate of the intangible assets are stated in note 6 to these financial statements. Full month's amortisation is charged in the month of addition, whereas, amortisation on disposals is charged up to the preceding month of derecognition.
C113: Gains or losses arising from derecognition of an intangible asset are measured as the difference between the net disposal proceeds and the carrying amount of the asset and are recognised in the statement of income and expenditure when the asset is derecognized.
B117: =+B96+0.1 -> 4.3 | C117: Trade and other payables
C119: Liabilities for trade and other payables are carried at cost which is the fair value of the consideration to be paid in the future for goods and services received, whether or not billed to the Company.
B122: =+B117+0.1 -> 4.4 | C122: Taxation
...

Sheet PPE-Note-4
A1: =+'Con 1-3 (New)'!A78+1 -> 5 | B1: PROPERTY AND EQUIPMENT
E3: Owned | N3: Right of use | O3: Total
E4: Leasehold land | F4: Building on leasehold land | G4: Generator | H4: Electrical installations | I4: Other equipments | J4: Furniture and fixture | K4: Computer equipment | L4: Vehicles | M4: Books | N4: Electrical installations
E7: ----------------------------------------------------------------------------------- Rupees --------------------------------------------------------------------------
B8: At June 30, 2016
B9: Cost | E9: 7171000 | F9: 22763815 | G9: 1244075 | H9: 1389085 | I9: 879714 | J9: 781677 | K9: 2761634 | L9: 3141295 | M9: 308439 | O9: =SUM(E9:M9) -> 40440734
B10: Accumulated depreciation | E10: 0 | F10: -5989140 | G10: -685771 | H10: -1146911 | I10: -688169 | J10: -705720 | K10: -2658747 | L10: -3141295 | M10: -308439 | O10: =(SUM(E10:M10)) -> -15324192
B12: Net book value | E12: =E9+E10 -> 7171000 | F12: =F9+F10 -> 16774675 | G12: =G9+G10 -> 558304 | H12: =H9+H10 -> 242174 | I12: =I9+I10 -> 191545 | J12: =J9+J10 -> 75957 | K12: =K9+K10 -> 102887 | L12: =L9+L10 -> 0 | M12: =M9+M10 -> 0 | O12: =O9+O10 -> 25116542
B14: Year ended June 30, 2017
B15: Opening net book value | E15: =E12 -> 7171000 | F15: =F12 -> 16774675 | G15: =G12 -> 558304 | H15: =H12 -> 242174 | I15: =I12 -> 191545 | J15: =J12 -> 75957 | K15: =K12 -> 102887 | L15: =L12 -> 0 | M15: =M12 -> 0 | N15: 0 | O15: =SUM(E15:M15) -> 25116542
B16: Additions (at cost) | E16: 0 | F16: 0 | G16: 0 | H16: 274200 | I16: 0 | J16: 86700 | K16: 5500 | L16: 0 | M16: 0 | N16: 0 | O16: =SUM(E16:N16) -> 366400
B17: Disposals
B18: Cost | E18: -5450000 | F18: 0 | G18: 0 | H18: 0 | I18: 0 | J18: 0 | K18: 0 | L18: 0 | M18: 0 | N18: 0 | O18: =SUM(E18:N18) -> -5450000
B19: Accumulated depreciation | E19: 0 | F19: 0 | G19: 0 | H19: 0 | I19: 0 | J19: 0 | K19: 0 | L19: 0 | M19: 0 | N19: 0 | O19: =SUM(E19:N19) -> 0
E20: =SUM(E18:E19) -> -5450000 | F20: =SUM(F18:F19) -> 0 | G20: =SUM(G18:G19) -> 0 | H20: =SUM(H18:H19) -> 0 | I20: =SUM(I18:I19) -> 0 | J20: =SUM(J18:J19) -> 0 | K20: =SUM(K18:K19) -> 0 | L20: =SUM(L18:L19) -> 0 | ... O20: =SUM(O18:O19) -> -5450000
B21: Depreciation charge for the year | E21: 0 | F21: -455276 | G21: -62204 | H21: -54435 | I21: -35696 | J21: -26920 | K21: -40420 | L21: 0 | M21: 0 | N21: 0 | O21: =SUM(E21:N21) -> -674951
B23: Net book value | E23: =+E15+E16+E20+E21 -> 1721000 | F23: =+F15+F16+F20+F21 -> 16319399 | G23: =+G15+G16+G20+G21 -> 496100 | H23: =+H15+H16+H20+H21 -> 461939 | I23: =+I15+I16+I20+I21 -> 155849 | J23: =+J15+J16+J20+J21 -> 135737 | K23: =+K15+K16+K20+K21 -> 67967 | L23: =+L15+L16+L20+L21 -> 0 | ... O23: =+O15+O16+O20+O21 -> 19357991
B25: At June 30, 2020
B26: Cost | E26: 1721000 | F26: 22763815 | G26: 1244075 | H26: 1789708 | I26: 911914 | J26: 868377 | K26: 2767134 | L26: 2534605 | M26: 308439 | N26: 3155750 | O26: =SUM(E26:N26) -> 38064817
B27: Accumulated depreciation | E27: 0 | F27: -7810244 | G27: -934587 | H27: -1434256 | I27: -806290 | J27: -785920 | K27: -2767134 | L27: -1915760 | M27: -308439 | N27: -858537 | O27: =SUM(E27:N27) -> -17621167
B28: Net book value | E28: =E26+E27 -> 1721000 | F28: =F26+F27 -> 14953571 | G28: =G26+G27 -> 309488 | H28: =H26+H27 -> 355452 | I28: =I26+I27 -> 105624 | J28: =J26+J27 -> 82457 | K28: =K26+K27 -> 0 | L28: =L26+L27 -> 618845 | ... O28: =O26+O27 -> 20443650
B30: Year ended June 30, 2024
B31: Opening net book value | E31: 1721000 | F31: 13587743 | G31: 122876 | H31: 171296 | I31: 46163 | J31: 40695 | K31: 35122 | L31: 0 | M31: 0 | N31: 1350488 | O31: 17075383
B32: Additions (at cost) | E32: 0 | F32: 0 | G32: 0 | H32: 0 | I32: 0 | J32: 0 | K32: 0 | L32: 0 | M32: 0 | N32: 0 | O32: 0
B33: Disposals | E33: 0 | F33: 0 | G33: 0 | H33: 0 | I33: 0 | J33: 0 | K33: 0 | L33: 0 | M33: 0 | N33: 0 | O33: 0
B34: Depreciation charge for the year | E34: 0 | F34: -455276 | G34: -62204 | H34: -41558 | I34: -15659 | J34: -9920 | K34: -35122 | L34: 0 | M34: 0 | N34: -315575 | O34: -935314
B36: Net book value | E36: 1721000 | F36: 13132467 | G36: 60672 | H36: 129738 | I36: 30504 | J36: 30775 | K36: 0 | L36: 0 | M36: 0 | N36: 1034913 | O36: 16140069
B38: At June 30, 2024
B39: Cost | E39: 1721000 | F39: 22763815 | G39: 1244075 | H39: 1789708 | I39: 911914 | J39: 868377 | K39: 2903533 | L39: 1108605 | M39: 308439 | N39: 3155750 | O39: 36775216
B40: Accumulated depreciation | E40: 0 | F40: -9631348 | G40: -1183403 | H40: -1659970 | I40: -881410 | J40: -837602 | K40: -2903533 | L40: -1108605 | M40: -308439 | N40: -2120837 | O40: -20635147
B42: Net book value | E42: 1721000 | F42: 13132467 | G42: 60672 | H42: 129738 | I42: 30504 | J42: 30775 | K42: 0 | L42: 0 | M42: 0 | N42: 1034913 | O42: 16140069
B44: Year ended June 30, 2025
B45: Opening net book value | E45: =E42 -> 1721000 | F45: =F42 -> 13132467 | G45: =G42 -> 60672 | H45: =H42 -> 129738 | I45: =I42 -> 30504 | J45: =J42 -> 30775 | K45: =K42 -> 0 | L45: =L42 -> 0 | ... N45: =N42 -> 1034913 | O45: =+SUM(E45:N45) -> 16140069
B46: Additions (at cost) | E46: 0 | F46: 0 | G46: 0 | H46: 25000 | I46: 0 | J46: 0 | L46: 0 | M46: 0 | N46: 0 | O46: =+SUM(E46:N46) -> 25000
B47: Transfer
B48: Cost | E48: 0 | F48: 0 | G48: 0 | H48: =-N48 -> 3155750 | I48: 0 | J48: 0 | K48: 0 | L48: 0 | M48: 0 | N48: -3155750 | O48: =+SUM(E48:N48) -> 0
B49: Accumulated depreciation | E49: 0 | F49: 0 | G49: 0 | H49: =-N49 -> -2120837 | I49: 0 | J49: 0 | K49: 0 | L49: 0 | M49: 0 | N49: 2120837 | O49: =+SUM(E49:N49) -> 0
E50: =SUM(E48:E49) -> 0 | F50: =SUM(F48:F49) -> 0 | G50: =SUM(G48:G49) -> 0 | H50: =SUM(H48:H49) -> 1034913 | I50: =SUM(I48:I49) -> 0 | J50: =SUM(J48:J49) -> 0 | K50: =SUM(K48:K49) -> 0 | L50: =SUM(L48:L49) -> 0 | ... N50: =SUM(N48:N49) -> -1034913 | O50: =+SUM(E50:N50) -> 0
B51: Depreciation charge for the year | E51: 0 | F51: -455276 | G51: -42323 | H51: =-40062-315575 -> -355637 | I51: -7068 | J51: -9680 | L51: 0 | M51: 0 | N51: 0 | O51: =+SUM(E51:N51) -> -869984
B53: Net book value | E53: =+E45+E46+E50+E51 -> 1721000 | F53: =+F45+F46+F50+F51 -> 12677191 | G53: =+G45+G46+G50+G51 -> 18349 | H53: =+H45+H46+H50+H51 -> 834014 | I53: =+I45+I46+I50+I51 -> 23436 | J53: =+J45+J46+J50+J51 -> 21095 | K53: =+K45+K46+K50+K51 -> 0 | L53: =+L45+L46+L50+L51 -> 0 | ... N53: =+N45+N46+N50+N51 -> 0 | O53: =+SUM(E53:N53) -> 15295085
...

Sheet Con 5-18
K1: 2026 | M1: 2025 | O1: 2024 | P1: 2017
A2: =+'PPE-Note-4'!A1+1 -> 6 | B2: INTANGIBLE ASSETS | I2: Note | K2: Rupees | M2: Rupees | O2: Rupees | P2: Rupees
B4: Net carrying value basis
B5: Opening net book value | K5: 5815 | M5: =O9 -> 8722 | O5: 13083 | P5: 0
B6: Add: | C6: Additions during the year | M6: 0 | O6: 0 | P6: 170118
B7: Less: | C7: Amortization for the year | K7: -2907 | M7: -2907 | O7: -4361 | P7: -37800
B9: Closing net book value | K9: =K5+K7 -> 2908 | M9: =M5+M6+M7 -> 5815 | O9: 8722 | P9: =P5+P6+P7 -> 132318
B11: Gross carrying value
B12: Cost | K12: 460096 | M12: =+O12+M6 -> 460096 | O12: 460096 | P12: 386398 | AB12: 797386
B13: Accumulated amortization | K13: =+K7+M13 -> -457188 | M13: =+O13+M7 -> -454281 | O13: -451374 | P13: -254080 | AB13: 566700
B15: Net book value | K15: =K12+K13 -> 2908 | M15: =M12+M13 -> 5815 | O15: 8722 | P15: =P12+P13 -> 132318
B17: Amortization rate | K17: 0.3333 | M17: 0.3333 | O17: 0.3333 | P17: 3
B19: INTANGIBLES ASSETS | R19: Rupees | T19: Rupees
B21: Cost | N21: #REF! | P21: #REF! | R21: #REF! | T21: 216280 | V21: =+T21/3 -> 72093.333
B22: Accumulated amortisation | K22: 5.1 | N22: #REF! | P22: #REF! | R22: #REF! | T22: -216280 | V22: =+V21*2 -> 144186.67 | W22: =+#REF! -> #REF!
V23: =+V21+V22 -> 216280
N24: =SUM(N21:N22) -> #REF! | P24: =SUM(P21:P22) -> #REF! | R24: =SUM(R21:R22) -> #REF! | T24: =SUM(T21:T22) -> 0 | W24: =+W22*3 -> #REF!
B25: 5.1 | C25: Computer software amortized at 3 years.
A26: =+A2+1 -> 7 | B26: INVESTMENTS (Held to maturity)
B28: Investment in term deposit receipt | K28: =+B32 -> 7.1 | M28: 0 | O28: 0 | P28: #REF! | R28: #REF! | T28: 6850000
P30: =SUM(P28:P28) -> #REF! | R30: =SUM(R28:R28) -> #REF! | T30: =SUM(T28:T28) -> 6850000
B32: =+A26+0.1 -> 7.1 | C32: Investment represents term deposit receipt of Bank Al-Habib for a period of one year at fixed rate of 5.8% per annum.
M35: 2020 | O35: 2019 | P35: 2017 | R35: 2016 | T35: 2015
A36: =+A2+1 -> 7 | B36: ADVANCES, DEPOSITS AND OTHER RECEIVABLES | P36: Rupees | R36: Rupees | T36: Rupees
B38: Staff loan | M38: =ROUND(GETPIVOTDATA("Sum of Amount",'Pivot 2025'!$A$3,"FSL1","Balance Sheet","FSL2","Current Assets","FSL3","Loans, Advances, Deposits, Prepayments And Receivables","FSL 4","Staff Loan"),0) -> #REF! | O38: 0 | P38: #REF! | R38: #REF! | T38: 1474046
B39: Advance against activities | M39: =ROUND(GETPIVOTDATA("Sum of Amount",'Pivot 2025'!$A$3,"FSL1","Balance Sheet","FSL2","Current Assets","FSL3","Loans, Advances, Deposits, Prepayments And Receivables","FSL 4","Advance Against Activities"),0) -> #REF! | O39: 602497 | P39: 699641 | R39: #REF! | T39: 3020380 | AA39: =M47-M39 -> #REF!
B40: Advance against salary | M40: =ROUND(GETPIVOTDATA("Sum of Amount",'Pivot 2025'!$A$3,"FSL1","Balance Sheet","FSL2","Current Assets","FSL3","Loans, Advances, Deposits, Prepayments And Receivables","FSL 4","Advance Against Salaries"),0) -> #REF! | O40: 30000
B41: Advance tax | M41: 0 | O41: 0
B42: Security deposit | M42: =ROUND(GETPIVOTDATA("Sum of Amount",'Pivot 2025'!$A$3,"FSL1","Balance Sheet","FSL2","Current Assets","FSL3","Loans, Advances, Deposits, Prepayments And Receivables","FSL 4","Security Depopsit"),0) -> #REF! | O42: 119700 | P42: #REF! | R42: #REF! | T42: 91500
B43: Prepaid insurance | M43: =ROUND(GETPIVOTDATA("Sum of Amount",'Pivot 2025'!$A$3,"FSL1","Balance Sheet","FSL2","Current Assets","FSL3","Loans, Advances, Deposits, Prepayments And Receivables","FSL 4","Prepaid Insurance"),0) -> #REF! | O43: 0 | P43: #REF! | R43: 0 | T43: 13375
B44: Prepayments | M44: 0 | O44: 0 | P44: #REF! | R44: #REF!
B45: Other receivables | M45: =ROUND(GETPIVOTDATA("Sum of Amount",'Pivot 2025'!$A$3,"FSL1","Balance Sheet","FSL2","Current Assets","FSL3","Loans, Advances, Deposits, Prepayments And Receivables","FSL 4","Other Receivables")+GETPIVOTDATA("Sum of Amount",'Pivot 2025'!$A$3,"FSL1","Balance Sheet","FSL2","Current Assets","FSL3","Loans, Advances, Deposits, Prepayments And Receivables","FSL 4","Others Receivable"),0) -> #REF! | O45: 958390 | P45: 746204 | R45: #REF! | T45: 1016122.8 | W45: =+#REF!-#REF! -> #REF! | AA45: =O45-M45 -> #REF!
M47: =SUM(M38:M45) -> #REF! | O47: =SUM(O38:O46) -> 1710587 | P47: =SUM(P38:P46) -> #REF! | R47: =SUM(R38:R46) -> #REF! | T47: =#REF!+T42 -> #REF! | W47: =R47-T47 -> #REF! | X47: =#REF!-#REF! -> #REF!
A49: =A36+1 -> 8 | B49: BANK BALANCES
B51: Current accounts | M51: =ROUND(GETPIVOTDATA("Sum of Amount",'Pivot 2025'!$A$3,"FSL1","Balance Sheet","FSL2","Current Assets","FSL3","Cash And Bank Balances","FSL 4","Cash With Banks In Current/Pls Accounts"),0) -> #REF! | O51: 2707493 | P51: 16766572 | R51: #REF!
B52: Savings account | M52: 0 | O52: 18079.549 | P52: 6246 | R52: 0 | AB52: =6262+7180 -> 13442
M54: =+M51+M52 -> #REF! | O54: =+O51+O52 -> 2725572.5 | P54: =+P51+P52 -> 16772818 | R54: =+R51+R52 -> #REF! | T54: =#REF!+#REF! -> #REF! | AB54: 2713755
A70: =+A49+1 -> 9 | B70: ACCRUED AND OTHER LIABILITIES | P70: Rupees | T70: Rupees
B72: Accrued expenses | M72: =-ROUND(GETPIVOTDATA("Sum of Amount",'Pivot 2025'!$A$3,"FSL1","Balance Sheet","FSL2","Current Liabilities","FSL3","Accrued, Payables And Other Liabilities","FSL 4","Accrued Expenses"),0) -> 6101653 | O72: 6523065 | P72: 1944840 | R72: #REF! | T72: 1166169 | AA72: =O72-M72 -> 421412
B73: Other liabilities | M73: =-ROUND(GETPIVOTDATA("Sum of Amount",'Pivot 2025'!$A$3,"FSL1","Balance Sheet","FSL2","Current Liabilities","FSL3","Accrued, Payables And Other Liabilities","FSL 4","Other Liabilities"),0)+510000 -> 3702870 | O73: =3186131+510000 -> 3696131 | P73: #REF! | R73: #REF! | T73: 45225 | AA73: =O73-M73 -> -6739
...

Sheet Note 16
A1: 16 | B1: FINANCIAL ASSETS AND LIABILITIES
E3: Markup bearing | H3: Non-Markup bearing | K3: 2015 | M3: 2014
E4: Maturity | F4: Maturity | G4: Sub-Total | H4: Closing | I4: Maturity | J4: Sub-Total
E5: upto one | F5: after one | H5: upto one | I5: after one
E6: year | F6: year | H6: year | I6: year | K6: Total | M6: Total
E7: ---------------------------------------------------------Rupees ------------------------------------------------------------
B9: Financial Assets
B10: Long term investments | E10: 6000000 | F10: 850000 | G10: =SUM(E10:F10) -> 6850000 | H10: 0 | I10: 0 | J10: =SUM(H10:I10) -> 0 | K10: =(G10+J10) -> 6850000 | M10: 6850000
B11: Advances and other receivables | E11: 0 | F11: =SUM(E11:E11) -> 0 | G11: =SUM(E11:F11) -> 0 | H11: 5523923.8 | I11: 0 | J11: =SUM(H11:I11) -> 5523923.8 | K11: =(G11+J11) -> 5523923.8 | M11: 6162964.8
B12: Cash and bank balances | E12: 0 | F12: =SUM(E12:E12) -> 0 | G12: =SUM(E12:F12) -> 0 | H12: 16227738 | I12: 0 | J12: =SUM(H12:I12) -> 16227738 | K12: =(G12+J12) -> 16227738 | M12: 16227738
E14: =+SUM(E10:E13) -> 6000000 | F14: =+SUM(F10:F13) -> 850000 | G14: =+SUM(G10:G13) -> 6850000 | H14: =+SUM(H10:H13) -> 21751662 | I14: =+SUM(I10:I13) -> 0 | J14: =+J10+J11+J12 -> 21751662 | K14: =SUM(K10:K12) -> 28601662 | M14: =SUM(M10:M12) -> 29240703
B16: Financial Liabilities
B17: Deferred liability - staff retirement gratuity | E17: 0 | F17: 0 | G17: 0 | H17: 0 | I17: 16377485 | J17: =SUM(H17:I17) -> 16377485 | K17: =(G17+J17) -> 16377485 | M17: 11681206
B18: Accrued, payables and other liabilities | E18: 0 | F18: 0 | G18: =SUM(E18:F18) -> 0 | H18: 1211394 | I18: 0 | J18: =SUM(H18:I18) -> 1211394 | K18: =(G18+J18) -> 1211394 | M18: 1111394
B19: Short term liabilities | E19: 0 | F19: 0 | G19: =SUM(E19:F19) -> 0 | H19: 8838057.8 | I19: 0 | J19: =SUM(H19:I19) -> 8838057.8 | K19: =(G19+J19) -> 8838057.8 | M19: 8838057.8
B20: Running finance | E20: 600004 | H20: 600004 | I20: 0 | J20: =SUM(H20:I20) -> 600004 | K20: =(G20+J20) -> 600004 | M20: 0
E21: =SUM(E17:E20) -> 600004 | F21: =SUM(F17:F19) -> 0 | G21: =SUM(G17:G19) -> 0 | H21: =SUM(H17:H19) -> 10049452 | I21: =SUM(I17:I19) -> 16377485 | J21: =SUM(J17:J19) -> 26426937 | K21: =SUM(K17:K19) -> 26426937 | M21: =SUM(M17:M20) -> 21630658
C87: Chief Executive Officer | H87: Director

Sheet Sheet9
A1: Account Code | B1: Account Description | C1: Title | D1: FSL1 | E1: FSL2 | F1: FSL3 | G1: FSL 4 | H1: Cost center | I1: Debit | J1: Credit | K1: Debit2 | L1: Credit2 | M1: Debit3 | N1: Credit3 | O1: Debit4 | P1: Credit4 | Q1: Debit5 | R1: Credit5 | S1: Amount
A2: 1-02-02-09-002 | B2: ACCUMULTED DEPRECIATION BOOKS | C2: 1-02-02-09-002-ACCUMULTED DEPRECIATION BOOKSPILER | D2: Balance Sheet | E2: Non Current Assets | F2: Tangible | G2: Acc Dep - Books | H2: PILER | I2: 0 | J2: 308439 | K2: 0 | L2: 0 | M2: 0 | N2: 308439 | Q2: 0 | R2: 308439 | S2: -308439
A3: 1-02-02-02-002 | B3: ACCUMULATED DEPRECIATION BUILD | C3: 1-02-02-02-002-ACCUMULATED DEPRECIATION BUILDPILER | D3: Balance Sheet | E3: Non Current Assets | F3: Tangible | G3: Acc Dep - Building On Leasehold Land | H3: PILER | I3: 0 | J3: 9631348 | K3: 0 | L3: 455276 | M3: 0 | N3: 10086624 | Q3: 0 | R3: 10086624 | S3: -10086624
A4: 1-02-02-07-002 | B4: ACCUMULATED DEPRECIATION COMPU | C4: 1-02-02-07-002-ACCUMULATED DEPRECIATION COMPUPILER | D4: Balance Sheet | E4: Non Current Assets | F4: Tangible | G4: Acc Dep - Computer Equipments | H4: PILER | I4: 5854 | J4: 2909388 | K4: 0 | L4: 0 | M4: 5854 | N4: 2909388 | P4: 0 | Q4: 5854 | R4: 2909388 | S4: -2903534
A5: 1-02-02-04-002 | B5: ACCUMULATED DEPRECIATION ELECT | C5: 1-02-02-04-002-ACCUMULATED DEPRECIATION ELECTPILER | D5: Balance Sheet | E5: Non Current Assets | F5: Tangible | G5: Acc Dep - Electrical Installations | H5: PILER | I5: 68126 | J5: 3848932 | K5: 0 | L5: 355637 | M5: 68126 | N5: 4204569 | Q5: 68126 | R5: 4204569 | S5: -4136443
A6: 1-02-02-06-002 | B6: ACCUMULATED DEPRECIATION F & F | C6: 1-02-02-06-002-ACCUMULATED DEPRECIATION F & FPILER | D6: Balance Sheet | E6: Non Current Assets | F6: Tangible | G6: Acc Dep - Furniture And Fixture | H6: PILER | I6: 45012 | J6: 882613 | K6: 0 | L6: 9680 | M6: 45012 | N6: 892293 | Q6: 45012 | R6: 892293 | S6: -847281
A7: 1-02-02-03-002 | B7: ACCUMULATED DEPRECIATION GENER | C7: 1-02-02-03-002-ACCUMULATED DEPRECIATION GENERPILER | D7: Balance Sheet | E7: Non Current Assets | F7: Tangible | G7: Acc Dep - Generator | H7: PILER | I7: 10368 | J7: 1193771 | K7: 0 | L7: 62204 | M7: 10368 | N7: 1255975 | O7: 19881 | Q7: 30249 | R7: 1255975 | S7: -1225726
A8: 1-02-02-05-002 | B8: ACCUMULATED DEPRECIATION OTHER | C8: 1-02-02-05-002-ACCUMULATED DEPRECIATION OTHERPILER | D8: Balance Sheet | E8: Non Current Assets | F8: Tangible | G8: Acc Dep - Other Equipments | H8: PILER | I8: 77185 | J8: 958595 | K8: 0 | L8: 7068 | M8: 77185 | N8: 965663 | Q8: 77185 | R8: 965663 | S8: -888478
A9: 1-02-02-08-002 | B9: ACCUMULTED DEPRECIATION MOTORS | C9: 1-02-02-08-002-ACCUMULTED DEPRECIATION MOTORSPILER | D9: Balance Sheet | E9: Non Current Assets | F9: Tangible | G9: Acc Dep - Vehicles | H9: PILER | I9: 1384994 | J9: 2493599 | K9: 0 | L9: 0 | M9: 1384994 | N9: 2493599 | Q9: 1384994 | R9: 2493599 | S9: -1108605
A10: 2-01-01-01-010 | B10: AUDIT FEE PAYABLE | C10: 2-01-01-01-010-AUDIT FEE PAYABLEPILER | D10: Balance Sheet | E10: Current Liabilities | F10: Accrued, Payables And Other Liabilities | G10: Accrued Expenses | H10: PILER | I10: 2133440 | J10: 2825362 | K10: 432000 | L10: 432000 | M10: 2565440 | N10: 3257362 | Q10: 2565440 | R10: 3257362 | S10: -691922
A11: 2-01-02-01-001 | B11: SALARIES PAYABLE | C11: 2-01-02-01-001-SALARIES PAYABLEPILER | D11: Balance Sheet | E11: Current Liabilities | F11: Accrued, Payables And Other Liabilities | G11: Accrued Expenses | H11: PILER | I11: 19048421 | J11: 18997551 | K11: 3551215 | L11: 3548477 | M11: 22599636 | N11: 22546028 | Q11: 22599636 | R11: 22546028 | S11: 53608
A12: 2-01-02-01-001 | B12: SALARIES PAYABLE | C12: 2-01-02-01-001-SALARIES PAYABLEUNICEF-3 | D12: Balance Sheet | E12: Current Liabilities | F12: Accrued, Payables And Other Liabilities | G12: Accrued Expenses | H12: UNICEF-3 | I12: 0 | J12: 3 | K12: 0 | L12: 0 | M12: 0 | N12: 3 | Q12: 0 | R12: 3 | S12: -3
A13: 2-01-02-01-001 | B13: SALARIES PAYABLE | C13: 2-01-02-01-001-SALARIES PAYABLEDAI | D13: Balance Sheet | E13: Current Liabilities | F13: Accrued, Payables And Other Liabilities | G13: Accrued Expenses | H13: DAI | I13: 3 | J13: 0 | K13: 0 | L13: 0 | M13: 3 | N13: 0 | Q13: 3 | R13: 0 | S13: 3
A14: 2-01-02-01-001 | B14: SALARIES PAYABLE | C14: 2-01-02-01-001-SALARIES PAYABLEGRC | D14: Balance Sheet | E14: Current Liabilities | F14: Accrued, Payables And Other Liabilities | G14: Accrued Expenses | H14: GRC | I14: 818916 | J14: 819916 | K14: 4805155 | L14: 4952509 | M14: 5624071 | N14: 5772425 | Q14: 5624071 | R14: 5772425 | S14: -148354
A15: 2-01-02-01-009 | B15: ACCRUED LIABILITIES - 2010 | C15: 2-01-02-01-009-ACCRUED LIABILITIES - 2010PILER | D15: Balance Sheet | E15: Current Liabilities | F15: Accrued, Payables And Other Liabilities | G15: Accrued Expenses | H15: PILER | I15: 0 | J15: 0 | K15: 0 | L15: 0 | M15: 0 | N15: 0 | Q15: 0 | R15: 0 | S15: 0
A16: 2-01-02-01-011 | B16: ACCURED EXPENSES | C16: 2-01-02-01-011-ACCURED EXPENSESTrocaire | D16: Balance Sheet | E16: Current Liabilities | F16: Accrued, Payables And Other Liabilities | G16: Accrued Expenses | H16: Trocaire | I16: 5519251 | J16: 4760392.3 | K16: 0 | L16: 0 | M16: 5519251 | N16: 4760392.3 | Q16: 5519251 | R16: 4760392.3 | S16: 758858.7
A17: 2-01-02-01-011 | B17: ACCURED EXPENSES | C17: 2-01-02-01-011-ACCURED EXPENSESPILER | D17: Balance Sheet | E17: Current Liabilities | F17: Accrued, Payables And Other Liabilities | G17: Accrued Expenses | H17: PILER | I17: 365378 | J17: 3507751.9 | K17: 0 | L17: 0 | M17: 365378 | N17: 3507751.9 | Q17: 365378 | R17: 3507751.9 | S17: -3142373.9
A18: 2-01-02-01-011 | B18: ACCURED EXPENSES | C18: 2-01-02-01-011-ACCURED EXPENSESDAI | D18: Balance Sheet | E18: Current Liabilities | F18: Accrued, Payables And Other Liabilities | G18: Accrued Expenses | H18: DAI | I18: 16420 | J18: 16420 | K18: 0 | L18: 0 | M18: 16420 | N18: 16420 | Q18: 16420 | R18: 16420 | S18: 0
A19: 2-01-02-01-011 | B19: ACCURED EXPENSES | C19: 2-01-02-01-011-ACCURED EXPENSESSHORT PROJECTS | D19: Balance Sheet | E19: Current Liabilities | F19: Accrued, Payables And Other Liabilities | G19: Accrued Expenses | H19: SHORT PROJECTS | I19: 200000 | J19: 740665.4 | K19: 0 | L19: 0 | M19: 200000 | N19: 740665.4 | Q19: 200000 | R19: 740665.4 | S19: -540665.4
... A22: 2-01-02-01-011 | B22: ACCURED EXPENSES | C22: 2-01-02-01-011-ACCURED EXPENSESETI | D22: Balance Sheet | E22: Current Liabilities | F22: Accrued, Payables And Other Liabilities | G22: Accrued Expenses | H22: ETI | I22: 0 | J22: 0 | K22: 0 | L22: 0 | M22: 0 | N22: 0 | Q22: 0 | R22: 0 | S22: 0
A23: 2-01-02-01-012 | B23: STAFF LOAN PAYABLE | C23: 2-01-02-01-012- STAFF LOAN PAYABLE | D23: Balance Sheet | E23: Current Liabilities | F23: Accrued, Payables And Other Liabilities | G23: Accrued Expenses | I23: 45000 | J23: 45000 | M23: 45000 | N23: 45000 | Q23: 45000 | R23: 45000 | S23: 0
A24: 2-01-02-01-011 | B24: ACCURED EXPENSES | C24: 2-01-02-01-011-ACCURED EXPENSESGRC | D24: Balance Sheet | E24: Current Liabilities | F24: Accrued, Payables And Other Liabilities | G24: Accrued Expenses | H24: GRC | I24: 0 | J24: 1735920 | K24: 566028 | L24: 0 | M24: 566028 | N24: 1735920 | Q24: 566028 | R24: 1735920 | S24: -1169892
A25: 1-02-02-07-004 | B25: AMMORTIZATION OF SOFTWARE LICS | C25: 1-02-02-07-004-AMMORTIZATION OF SOFTWARE LICSPILER | D25: Balance Sheet | E25: Non Current Assets | F25: Intangible | G25: Accumulated Amortisation | H25: PILER | I25: 7487 | J25: 458860.67 | K25: 0 | L25: 115326 | M25: 7487 | N25: 574186.67 | O25: 115326 | Q25: 122813 | R25: 574186.67 | S25: -451373.67
A26: 1-02-02-07-004 | B26: AMMORTIZATION OF SOFTWARE LICS | C26: Ammortization Of Software Lics | D26: Balance Sheet | E26: Non Current Assets | F26: Intangible | G26: Accumulated Amortisation | H26: ETI | I26: 0 | J26: 0 | K26: 0 | L26: 0 | M26: 0 | N26: 0 | Q26: 0 | R26: 0 | S26: 0
A27: 1-01-02-03-003 | B27: ADVANCE TO GOHAR ALI | C27: 1-01-02-03-003-ADVANCE TO GOHAR ALIPILER | D27: Balance Sheet | E27: Current Assets | F27: Loans, Advances, Deposits, Prepayments And Receivables | G27: Advance Against Activities | H27: PILER | I27: 2450 | J27: 0 | K27: 0 | L27: 0 | M27: 2450 | N27: 0 | Q27: 2450 | R27: 0 | S27: 2450
A28: 1-01-02-03-003 | B28: ADVANCE TO GOHAR ALI | C28: 1-01-02-03-003-ADVANCE TO GOHAR ALITDH | D28: Balance Sheet | E28: Current Assets | F28: Loans, Advances, Deposits, Prepayments And Receivables | G28: Advance Against Activities | H28: TDH | I28: 0 | J28: 2450 | K28: 0 | L28: 0 | M28: 0 | N28: 2450 | Q28: 0 | R28: 2450 | S28: -2450
A29: 1-01-02-03-008 | B29: ADVANCE TO KHADIM HUSSAIN | C29: 1-01-02-03-008-ADVANCE TO KHADIM HUSSAINPILER | D29: Balance Sheet | E29: Current Assets | F29: Loans, Advances, Deposits, Prepayments And Receivables | G29: Advance Against Activities | H29: PILER | I29: 2406928 | J29: 2436928 | K29: 2317470 | L29: 2317470 | M29: 4724398 | N29: 4754398 | O29: 30000 | Q29: 4754398 | R29: 4754398 | S29: 0
A30: 1-01-02-03-008 | B30: ADVANCE TO KHADIM HUSSAIN | C30: 1-01-02-03-008-ADVANCE TO KHADIM HUSSAINICCO | D30: Balance Sheet | E30: Current Assets | F30: Loans, Advances, Deposits, Prepayments And Receivables | G30: Advance Against Activities | H30: ICCO | I30: 50200 | J30: 0 | K30: 0 | L30: 0 | M30: 50200 | N30: 0 | P30: 50200 | Q30: 50200 | R30: 50200 | S30: 0
A31: 1-01-02-03-008 | B31: ADVANCE TO KHADIM HUSSAIN | C31: 1-01-02-03-008-ADVANCE TO KHADIM HUSSAINSHORT PROJECTS | D31: Balance Sheet | E31: Current Assets | F31: Loans, Advances, Deposits, Prepayments And Receivables | G31: Advance Against Activities | H31: SHORT PROJECTS | I31: 303365 | J31: 227500 | K31: 0 | L31: 0 | M31: 303365 | N31: 227500 | P31: 75865 | Q31: 303365 | R31: 303365 | S31: 0
A32: 1-01-02-03-008 | B32: Advance To Khadim Hussain | C32: 1-01-02-03-008-Advance To Khadim HussainOpen Society | D32: Balance Sheet | E32: Current Assets | F32: Loans, Advances, Deposits, Prepayments And Receivables | G32: Advance Against Activities | H32: Open Society | I32: 98530 | J32: 98530 | M32: 98530 | N32: 98530 | Q32: 98530 | R32: 98530 | S32: 0
A33: 1-01-02-03-008 | B33: ADVANCE TO KHADIM HUSSAIN | C33: 1-01-02-03-008-ADVANCE TO KHADIM HUSSAINDAI | D33: Balance Sheet | E33: Current Assets | F33: Loans, Advances, Deposits, Prepayments And Receivables | G33: Advance Against Activities | H33: DAI | I33: 15150 | J33: 6000 | K33: 0 | L33: 0 | M33: 15150 | N33: 6000 | P33: 9150 | Q33: 15150 | R33: 15150 | S33: 0
A34: 1-01-02-03-008 | B34: ADVANCE TO KHADIM HUSSAIN | C34: 1-01-02-03-008-ADVANCE TO KHADIM HUSSAINGRC | D34: Balance Sheet | E34: Current Assets | F34: Loans, Advances, Deposits, Prepayments And Receivables | G34: Advance Against Activities | H34: GRC | I34: 350100 | J34: 350100 | K34: 330000 | L34: 310000 | M34: 680100 | N34: 660100 | P34: 20000 | Q34: 680100 | R34: 680100 | S34: 0
A35: 1-01-02-03-008 | B35: ADVANCE TO KHADIM HUSSAIN | C35: 1-01-02-03-008-ADVANCE TO KHADIM HUSSAINGRC Own | D35: Balance Sheet | E35: Current Assets | F35: Loans, Advances, Deposits, Prepayments And Receivables | G35: Advance Against Activities | H35: GRC Own | I35: 0 | J35: 0 | K35: 186000 | L35: 0 | M35: 186000 | N35: 0 | Q35: 186000 | R35: 0 | S35: 186000
A36: 1-01-02-03-020 | B36: ADVANCE TO ABBAS HAIDER | C36: 1-01-02-03-020-ADVANCE TO ABBAS HAIDERPILER | D36: Balance Sheet | E36: Current Assets | F36: Loans, Advances, Deposits, Prepayments And Receivables | G36: Advance Against Activities | H36: PILER | I36: 564350 | J36: 477300 | K36: 42000 | L36: 0 | M36: 606350 | N36: 477300 | P36: 87050 | Q36: 606350 | R36: 564350 | S36: 42000
A37: 1-01-02-03-020 | B37: ADVANCE TO ABBAS HAIDER | C37: 1-01-02-03-020-ADVANCE TO ABBAS HAIDERSHORT PROJECTS | D37: Balance Sheet | E37: Current Assets | F37: Loans, Advances, Deposits, Prepayments And Receivables | G37: Advance Against Activities | H37: SHORT PROJECTS | I37: 647000 | J37: 697000 | K37: 0 | L37: 0 | M37: 647000 | N37: 697000 | O37: 50000 | Q37: 697000 | R37: 697000 | S37: 0
A38: 1-01-02-03-020 | B38: ADVANCE TO ABBAS HAIDER | C38: 1-01-02-03-020-ADVANCE TO ABBAS HAIDERRRCCHR | D38: Balance Sheet | E38: Current Assets | F38: Loans, Advances, Deposits, Prepayments And Receivables | G38: Advance Against Activities | H38: RRCCHR | I38: 4000 | J38: 0 | K38: 0 | L38: 0 | M38: 4000 | N38: 0 | P38: 4000 | Q38: 4000 | R38: 4000 | S38: 0
A39: 1-01-02-03-041 | B39: ADVANCE TO M.RAFIQUE | C39: 1-01-02-03-041-ADVANCE TO M.RAFIQUETDH & MI | D39: Balance Sheet | E39: Current Assets | F39: Loans, Advances, Deposits, Prepayments And Receivables | G39: Advance Against Activities | H39: TDH & MI | I39: 300000 | J39: 5050 | K39: 0 | L39: 300000 | M39: 300000 | N39: 305050 | O39: 5050 | Q39: 305050 | R39: 305050 | S39: 0
A40: 1-01-02-03-116 | B40: Advance to Zameer Awan | C40: 1-01-02-03-116-Advance to Zameer AwanPILER | D40: Balance Sheet | E40: Current Assets | F40: Loans, Advances, Deposits, Prepayments And Receivables | G40: Advance Against Activities | H40: PILER | I40: 70000 | J40: 70000 | K40: 321000 | L40: 321000 | M40: 391000 | N40: 391000 | Q40: 391000 | R40: 391000 | S40: 0
A41: 1-01-02-03-123 | B41: Advance against Expenses | C41: 1-01-02-03-123Advance against Expenses | D41: Balance Sheet | E41: Current Assets | F41: Loans, Advances, Deposits, Prepayments And Receivables | G41: Advance Against Activities | H41: PILER | I41: 231282 | J41: 70000 | K41: 560500 | L41: 670500 | M41: 791782 | N41: 740500 | Q41: 791782 | R41: 740500 | S41: 51282
A42: 1-01-02-03-123 | B42: Advance against Expenses | C42: 1-01-02-03-123-Advance against ExpensesGRC | D42: Balance Sheet | E42: Current Assets | F42: Loans, Advances, Deposits, Prepayments And Receivables | G42: Advance Against Activities | H42: GRC | I42: 0 | J42: 0 | K42: 134750 | L42: 186032 | M42: 134750 | N42: 186032 | Q42: 134750 | R42: 186032 | S42: -51282
...

Sheet Pivot 2025
A3: Row Labels | B3: Sum of Debit5 | C3: Sum of Credit5 | D3: Sum of Amount
A4: - | B4: 1.0794097e+08 | C4: 1.0794097e+08 | D4: 0.47
A5: Inter Project Balances | B5: 1.0794097e+08 | C5: 1.0794097e+08 | D5: 0.47
A6: Inter Project Balances | B6: 1.0794097e+08 | C6: 1.0794097e+08 | D6: 0.47
A7: Inter Project Balances | B7: 1.0794097e+08 | C7: 1.0794097e+08 | D7: 0.47
A8: Balance Sheet | B8: 4.065747e+08 | C8: 4.0319681e+08 | D8: 3377886.1
A9: Current Assets | B9: 1.8015129e+08 | C9: 1.7190403e+08 | D9: 8247263.5
A10: Current Liabilities | B10: 98013100 | C10: 1.4809864e+08 | D10: -50085538
A11: Accrued, Payables And Other Liabilities | B11: 45186488 | C11: 54481011 | D11: -9294522.9
A12: Accrued Expenses | B12: 37889061 | C12: 43990714 | D12: -6101652.6
A13: Other Liabilities | B13: 7297427 | C13: 10490297 | D13: -3192870.3
A14: Provision for taxation | B14: 0 | C14: 0 | D14: 0
A15: Short Term Liabilities | B15: 52826612 | C15: 93617627 | D15: -40791015
... A210: Grand Total | B210: 5.6205653e+08 | C210: 5.6205653e+08 | D210: 0.85163715

Sheet Trial Balance June 2025
A1: Pakistan Inst. of Labour Edu & Research | AD1: 5-01-02-74-004
A2: Six Column Trial Balance | J2: =J3-J4 -> 16140068 | AD2: 5-01-02-74-005
A3: For the year ended June 30, 2023 | I3: . | J3: 16140069 | AD3: 2-01-01-02-033
J4: =+I5-J5 -> 0.82163721 | L4: =+K5-L5 -> 0.029999986 | N4: =+M5-N5 -> 0.85163724 | P4: =+O5-P5 -> 0 | R4: =+Q5-R5 -> 0.85163736 | U4: =U5-S5 -> 15418234
I5: =SUBTOTAL(9,I9:I522) -> 4.4686625e+08 | J5: =SUBTOTAL(9,J9:J522) -> 4.4686625e+08 | K5: =SUBTOTAL(9,K9:K522) -> 1.1032708e+08 | L5: =SUBTOTAL(9,L9:L522) -> 1.1032708e+08 | M5: =SUBTOTAL(9,M9:M522) -> 5.5719334e+08 | N5: =SUBTOTAL(9,N9:N522) -> 5.5719333e+08 | O5: =SUBTOTAL(9,O9:O522) -> 4863198.3 | P5: =SUBTOTAL(9,P9:P522) -> 4863198.3 | ... S5: =SUBTOTAL(9,S9:S522) -> 0.85163716 | U5: 15418235
W6: =+V7-W7 -> 21386082 | Y6: =+X7-Y7 -> -34593.96 | AA6: =+Z7-AA7 -> -1.86 | AC6: =+AB7-AC7 -> 356829.1 | AE6: =+AD7-AE7 -> 8568.63 | AG6: =+AF7-AG7 -> -286659.63 | AI6: =+AH7-AI7 -> 20000 | AK6: =+AJ7-AK7 -> 1179824.2 | AM6: =+AL7-AM7 -> 0 | AO6: =+AN7-AO7 -> -247794.3 | AQ6: =+AP7-AQ7 -> -19.09 | AS6: =+AR7-AS7 -> 171767.25 | AU6: =+AT7-AU7 -> 70335.04 | AW6: =+AV7-AW7 -> -20757003 | AY6: =+AX7-AY7 -> 100.1 | BA6: =+AZ7-BA7 -> -4039.55 | BC6: =+BB7-BC7 -> -753174.34 | BE6: =+BD7-BE7 -> -50200.23 | BG6: =+BF7-BG7 -> 1674159
A7: Account Code | B7: Account Description | C7: Title | D7: FSL1 | E7: FSL2 | F7: Accrued, Payables And Other Liabilities | G7: FSL 4 | H7: Cost center | I7: Opening Balance | K7: Current Activity | M7: Closing Balance | O7: Adjustments | Q7: Adjusted Closing Balance | S7: Net balance | V7: =SUBTOTAL(9,V9:V522) -> 3.281445e+08 | W7: =SUBTOTAL(9,W9:W522) -> 3.0675842e+08 | X7: =SUBTOTAL(9,X9:X522) -> 2155230 | Y7: =SUBTOTAL(9,Y9:Y522) -> 2189824 | Z7: =SUBTOTAL(9,Z9:Z522) -> 5377732.1 | AA7: =SUBTOTAL(9,AA9:AA522) -> 5377734 | AB7: =SUBTOTAL(9,AB9:AB522) -> 793328.2 | AC7: =SUBTOTAL(9,AC9:AC522) -> 436499.1 | ... BG7: =SUBTOTAL(9,BG9:BG522) -> 2642556
A8: Account Code | B8: Account Description | C8: Title | D8: FSL1 | E8: FSL2 | F8: FSL3 | G8: FSL 4 | H8: Cost center | I8: Debit | J8: Credit | K8: Debit | L8: Credit | M8: Debit | N8: Credit | O8: Debit | P8: Credit | Q8: Debit | R8: Credit | S8: Amount | V8: PILER | X8: TDH & MI | Z8: TDH | AB8: TAF | AD8: ETI | AF8: UNICEF-2 | AH8: UNICEF-3 | AJ8: Trocaire | AL8: FOSI | AN8: DAI | AP8: Deezire | AR8: FNV | AT8: ICCO Pak | AV8: Open Society | AX8: TDH Pak | AZ8: RRCCHR | BB8: SHORT PROJECTS | BD8: ICCO | BF8: Unicef
A9: 1-01-01-01-001 | B9: CASH IN HAND | C9: 1-01-01-01-001-CASH IN HANDPILER | D9: Balance Sheet | E9: Current Assets | F9: Cash And Bank Balances | G9: Cash With Banks In Current/Pls Accounts | H9: PILER | I9: 3 | K9: 0 | L9: 0 | M9: =+I9+K9 -> 3 | N9: =+J9+L9 -> 0 | Q9: =+M9+O9 -> 3 | R9: =+N9+P9 -> 0 | S9: =+Q9-R9 -> 3 | V9: =IF($V$8=$H9,$Q9,0) -> 3 | W9: =IF($V$8=$H9,$R9,0) -> 0 | X9: =IF($X$8=$H9,$Q9,0) -> 0 | Y9: =IF($X$8=$H9,$R9,0) -> 0 | Z9: =IF($Z$8=$H9,$Q9,0) -> 0 | AA9: =IF($Z$8=$H9,$R9,0) -> 0 | AB9: =IF($AB$8=$H9,$Q9,0) -> 0 | AC9: =IF($AB$8=$H9,$R9,0) -> 0 | AD9: =IF($AD$8=$H9,$Q9,0) -> 0 | AE9: =IF($AD$8=$H9,$R9,0) -> 0 | AF9: =IF($AF$8=$H9,$Q9,0) -> 0 | AG9: =IF($AF$8=$H9,$R9,0) -> 0 | AH9: =IF($AH$8=$H9,$Q9,0) -> 0 | AI9: =IF($AH$8=$H9,$R9,0) -> 0 | AJ9: =IF($AJ$8=$H9,$Q9,0) -> 0 | AK9: =IF($AJ$8=$H9,$R9,0) -> 0 | AL9: =IF($AL$8=$H9,$Q9,0) -> 0 | AM9: =IF($AL$8=$H9,$R9,0) -> 0 | AN9: =IF($AN$8=$H9,$Q9,0) -> 0 | AO9: =IF($AN$8=$H9,$R9,0) -> 0 | AP9: =IF($AP$8=$H9,$Q9,0) -> 0 | AQ9: =IF($AP$8=$H9,$R9,0) -> 0 | AR9: =IF($AR$8=$H9,$Q9,0) -> 0 | AS9: =IF($AR$8=$H9,$R9,0) -> 0 | AT9: =IF($AT$8=$H9,$Q9,0) -> 0 | AU9: =IF($AT$8=$H9,$R9,0) -> 0 | AV9: =IF($AV$8=$H9,$Q9,0) -> 0 | AW9: =IF($AV$8=$H9,$R9,0) -> 0 | AX9: =IF($AX$8=$H9,$Q9,0) -> 0 | AY9: =IF($AX$8=$H9,$R9,0) -> 0 | AZ9: =IF($AZ$8=$H9,$Q9,0) -> 0 | BA9: =IF($AZ$8=$H9,$R9,0) -> 0 | BB9: =IF($BB$8=$H9,$Q9,0) -> 0 | BC9: =IF($BB$8=$H9,$R9,0) -> 0 | BD9: =IF($BD$8=$H9,$Q9,0) -> 0 | BE9: =IF($BD$8=$H9,$R9,0) -> 0 | BF9: =IF($BF$8=$H9,$Q9,0) -> 0 | BG9: =IF($BF$8=$H9,$R9,0) -> 0
A10: 1-01-01-01-001 | B10: CASH IN HAND | C10: 1-01-01-01-001-CASH IN HANDKarachi | D10: Balance Sheet | E10: Current Assets | F10: Cash And Bank Balances | G10: Cash With Banks In Current/Pls Accounts | H10: Karachi | I10: 0 | J10: 0 | K10: 0 | L10: 0 | M10: =+I10+K10 -> 0 | N10: =+J10+L10 -> 0 | Q10: =+M10+O10 -> 0 | R10: =+N10+P10 -> 0 | S10: =+Q10-R10 -> 0 | V10: =IF($V$8=$H10,$Q10,0) -> 0 | W10: =IF($V$8=$H10,$R10,0) -> 0 | X10: =IF($X$8=$H10,$Q10,0) -> 0 | Y10: =IF($X$8=$H10,$R10,0) -> 0 | Z10: =IF($Z$8=$H10,$Q10,0) -> 0 | AA10: =IF($Z$8=$H10,$R10,0) -> 0 | AB10: =IF($AB$8=$H10,$Q10,0) -> 0 | AC10: =IF($AB$8=$H10,$R10,0) -> 0 | AD10: =IF($AD$8=$H10,$Q10,0) -> 0 | AE10: =IF($AD$8=$H10,$R10,0) -> 0 | AF10: =IF($AF$8=$H10,$Q10,0) -> 0 | AG10: =IF($AF$8=$H10,$R10,0) -> 0 | AH10: =IF($AH$8=$H10,$Q10,0) -> 0 | AI10: =IF($AH$8=$H10,$R10,0) -> 0 | AJ10: =IF($AJ$8=$H10,$Q10,0) -> 0 | AK10: =IF($AJ$8=$H10,$R10,0) -> 0 | AL10: =IF($AL$8=$H10,$Q10,0) -> 0 | AM10: =IF($AL$8=$H10,$R10,0) -> 0 | AN10: =IF($AN$8=$H10,$Q10,0) -> 0 | AO10: =IF($AN$8=$H10,$R10,0) -> 0 | AP10: =IF($AP$8=$H10,$Q10,0) -> 0 | AQ10: =IF($AP$8=$H10,$R10,0) -> 0 | AR10: =IF($AR$8=$H10,$Q10,0) -> 0 | AS10: =IF($AR$8=$H10,$R10,0) -> 0 | AT10: =IF($AT$8=$H10,$Q10,0) -> 0 | AU10: =IF($AT$8=$H10,$R10,0) -> 0 | AV10: =IF($AV$8=$H10,$Q10,0) -> 0 | AW10: =IF($AV$8=$H10,$R10,0) -> 0 | AX10: =IF($AX$8=$H10,$Q10,0) -> 0 | AY10: =IF($AX$8=$H10,$R10,0) -> 0 | AZ10: =IF($AZ$8=$H10,$Q10,0) -> 0 | BA10: =IF($AZ$8=$H10,$R10,0) -> 0 | BB10: =IF($BB$8=$H10,$Q10,0) -> 0 | BC10: =IF($BB$8=$H10,$R10,0) -> 0 | BD10: =IF($BD$8=$H10,$Q10,0) -> 0 | BE10: =IF($BD$8=$H10,$R10,0) -> 0 | BF10: =IF($BF$8=$H10,$Q10,0) -> 0 | BG10: =IF($BF$8=$H10,$R10,0) -> 0
A11: 1-01-01-02-002 | B11: PILER OWN BAHL A/C. 818-04-2 | C11: 1-01-01-02-002-PILER OWN BAHL A/C. 818-04-2PILER | D11: Balance Sheet | E11: Current Assets | F11: Cash And Bank Balances | G11: Cash With Banks In Current/Pls Accounts | H11: PILER | I11: 143120 | J11: 0 | K11: 0 | L11: 0 | M11: =+I11+K11 -> 143120 | N11: =+J11+L11 -> 0 | Q11: =+M11+O11 -> 143120 | R11: =+N11+P11 -> 0 | S11: =+Q11-R11 -> 143120 | V11: =IF($V$8=$H11,$Q11,0) -> 143120 | W11: =IF($V$8=$H11,$R11,0) -> 0 | X11: =IF($X$8=$H11,$Q11,0) -> 0 | Y11: =IF($X$8=$H11,$R11,0) -> 0 | Z11: =IF($Z$8=$H11,$Q11,0) -> 0 | AA11: =IF($Z$8=$H11,$R11,0) -> 0 | AB11: =IF($AB$8=$H11,$Q11,0) -> 0 | AC11: =IF($AB$8=$H11,$R11,0) -> 0 | AD11: =IF($AD$8=$H11,$Q11,0) -> 0 | AE11: =IF($AD$8=$H11,$R11,0) -> 0 | AF11: =IF($AF$8=$H11,$Q11,0) -> 0 | AG11: =IF($AF$8=$H11,$R11,0) -> 0 | AH11: =IF($AH$8=$H11,$Q11,0) -> 0 | AI11: =IF($AH$8=$H11,$R11,0) -> 0 | AJ11: =IF($AJ$8=$H11,$Q11,0) -> 0 | AK11: =IF($AJ$8=$H11,$R11,0) -> 0 | AL11: =IF($AL$8=$H11,$Q11,0) -> 0 | AM11: =IF($AL$8=$H11,$R11,0) -> 0 | AN11: =IF($AN$8=$H11,$Q11,0) -> 0 | AO11: =IF($AN$8=$H11,$R11,0) -> 0 | AP11: =IF($AP$8=$H11,$Q11,0) -> 0 | AQ11: =IF($AP$8=$H11,$R11,0) -> 0 | AR11: =IF($AR$8=$H11,$Q11,0) -> 0 | AS11: =IF($AR$8=$H11,$R11,0) -> 0 | AT11: =IF($AT$8=$H11,$Q11,0) -> 0 | AU11: =IF($AT$8=$H11,$R11,0) -> 0 | AV11: =IF($AV$8=$H11,$Q11,0) -> 0 | AW11: =IF($AV$8=$H11,$R11,0) -> 0 | AX11: =IF($AX$8=$H11,$Q11,0) -> 0 | AY11: =IF($AX$8=$H11,$R11,0) -> 0 | AZ11: =IF($AZ$8=$H11,$Q11,0) -> 0 | BA11: =IF($AZ$8=$H11,$R11,0) -> 0 | BB11: =IF($BB$8=$H11,$Q11,0) -> 0 | BC11: =IF($BB$8=$H11,$R11,0) -> 0 | BD11: =IF($BD$8=$H11,$Q11,0) -> 0 | BE11: =IF($BD$8=$H11,$R11,0) -> 0 | BF11: =IF($BF$8=$H11,$Q11,0) -> 0 | BG11: =IF($BF$8=$H11,$R11,0) -> 0
